// const throwAnError = async () => {
//   throw new Error('throwAnError()')
//   // setTimeout(() => {
//   //   throw new Error('throwAnError()')
//   // }, 1000)
// }




// const callIt = async () => {
//   try {
//     await throwAnError()
//   } catch (e) {
//     console.log('it threw')
//   }
// }